Workbook
Name BedsPlanted: Optimizer!$B$17
Name BedsUnused: Optimizer!$B$18
Name BlendedRate: Optimizer!$B$16
Name BreakEven_BedsPlanted: Optimizer!$B$42
Name BreakEven_BedsUnused: Optimizer!$B$43
Name BreakEven_BlendedRate: Optimizer!$B$41
Name BreakEven_Carrot_Beds: Optimizer!$B$32
Name BreakEven_LaborCost: Optimizer!$B$40
Name BreakEven_Mesclun_Beds: Optimizer!$B$33
Name BreakEven_OwnHoursUsed: Optimizer!$B$37
Name BreakEven_SeasonProfit: Optimizer!$B$44
Name BreakEven_TempHours: Optimizer!$B$38
Name BreakEven_TempHoursMax: Optimizer!$B$39
Name BreakEven_Tomato_Beds: Optimizer!$B$31
Name BreakEven_TotalHours: Optimizer!$B$36
Name BreakEvenBeds: Optimizer!$B$45
Name Carrot_Beds: Optimizer!$B$7
Name Carrot_BreakEvenBeds: Schedules!$N$6
Name Carrot_Cap: Inputs!$B$10
Name Carrot_DimRate: Inputs!$B$14
Name Carrot_Fertilizer: Inputs!$B$13
Name Carrot_HoursPerWeek: Inputs!$B$12
Name Carrot_LastPossibleProfitableBed: Schedules!$N$3
Name Carrot_LastProfitableBed: Schedules!$N$5
Name Carrot_Revenue: Inputs!$B$11
Name DailyPenalty: Inputs!$B$32
Name FertilizerShare: Optimizer!$C$24
Name FixedCost: Inputs!$B$22
Name FixedShare: Optimizer!$C$25
Name HourlyLoss: Inputs!$B$31
Name LaborCost: Optimizer!$B$15
Name LaborShare: Optimizer!$C$23
Name Limit_Carrot_Cap: Optimizer!$F$14
Name Limit_Mesclun_Cap: Optimizer!$F$15
Name Limit_Tomato_Cap: Optimizer!$F$13
Name Limit_TotalBeds: Optimizer!$F$16
Name MaxTemps: Inputs!$B$27
Name Mesclun_Beds: Optimizer!$B$8
Name Mesclun_BreakEvenBeds: Schedules!$X$6
Name Mesclun_Cap: Inputs!$B$15
Name Mesclun_DimRate: Inputs!$B$19
Name Mesclun_Fertilizer: Inputs!$B$18
Name Mesclun_HoursPerWeek: Inputs!$B$17
Name Mesclun_LastPossibleProfitableBed: Schedules!$X$3
Name Mesclun_LastProfitableBed: Schedules!$X$5
Name Mesclun_Revenue: Inputs!$B$16
Name OwnDayHours: Inputs!$B$35
Name OwnDaysPerWeek: Inputs!$B$36
Name OwnEfficiency: 'What if'!$B$25
Name OwnHours: Inputs!$B$23
Name OwnHoursUsed: Optimizer!$B$12
Name OwnPayBasisHours: Inputs!$B$41
Name OwnRate: Inputs!$B$24
Name OwnSeasonPay: Inputs!$B$40
Name SeasonProfit: Optimizer!$B$19
Name SeasonWeeks: Inputs!$B$21
Name TempDayHours: Inputs!$B$33
Name TempDaysPerWeek: Inputs!$B$34
Name TempEfficiency: 'What if'!$B$24
Name TempHours: Optimizer!$B$13

Sheet README
A1: Farm planting model: README
A3: What this model is for
A4: It decides how many beds of tomatoes, carrots and mesclun to plant, whether planting fewer than 64 beds makes sense, and whether the season covers the $20,000 fixed cost. It is built from capabilities/marginal-analysis/spec.md: if the workbook and the spec disagree, fix the spec and rebuild.
A6: What each tab does
A7: Inputs: every number from the case, named. Change one here and the whole workbook recalculates.
A8: Schedules: one table per crop, one row per bed, showing the hours and cost one extra bed adds (the marginal cost schedule), worked out as if that crop were the only one planted.
A9: Optimizer: the three bed counts Solver changes, the farm's labor and profit, cost shares, and a second setup that finds the fewest beds that still cover the fixed cost.
A10: Checks: pass/fail cells, green when met, plus the checks you run by hand.
A11: What if: the same model with workers who tire through the day and the week. A side project; it never changes the other tabs.
A13: How to change an input
A14: Go to Inputs and type a new value in a blue cell. Then re-run Solver, because the best mix may change.
A16: How to run Solver
... A26: Claude built the workbook from Brian's spec on 2026-10-27. Brian runs Solver and the checks. See prompt-log.md.

Sheet Inputs
A1: Inputs: the named contract
A2: Blue values are inputs. Change a value here and every other tab recalculates. Nothing else belongs on this tab.
A4: Name | B4: Value | C4: Unit | D4: Source
A5: Tomato_Cap | B5: 20 | C5: beds | D5: Case facts, crop table
A6: Tomato_Revenue | B6: 8800 | C6: $ per bed | D6: Case facts, crop table
A7: Tomato_HoursPerWeek | B7: 2.5 | C7: labor hours per week per bed | D7: Case facts, crop table
A8: Tomato_Fertilizer | B8: 880 | C8: $ per bed | D8: Case facts, crop table
A9: Tomato_DimRate | B9: 0.1 | C9: added labor per bed planted | D9: Case facts, crop table
A10: Carrot_Cap | B10: 20 | C10: beds | D10: Case facts, crop table
A11: Carrot_Revenue | B11: 2094 | C11: $ per bed | D11: Case facts, crop table
A12: Carrot_HoursPerWeek | B12: =50/60 -> 0.83333333 | C12: labor hours per week per bed | D12: Case facts, crop table (printed as 0.833, which is 50 minutes a week rounded)
A13: Carrot_Fertilizer | B13: 440 | C13: $ per bed | D13: Case facts, crop table
A14: Carrot_DimRate | B14: 0.025 | C14: added labor per bed planted | D14: Case facts, crop table
A15: Mesclun_Cap | B15: 30 | C15: beds | D15: Case facts, crop table
A16: Mesclun_Revenue | B16: 2700 | C16: $ per bed | D16: Case facts, crop table
A17: Mesclun_HoursPerWeek | B17: 1.25 | C17: labor hours per week per bed | D17: Case facts, crop table
A18: Mesclun_Fertilizer | B18: 880 | C18: $ per bed | D18: Case facts, crop table
A19: Mesclun_DimRate | B19: 0.0125 | C19: added labor per bed planted | D19: Case facts, crop table
A20: TotalBeds | B20: 64 | C20: beds (maximum) | D20: Case facts, farm inputs
A21: SeasonWeeks | B21: 36 | C21: weeks | D21: Case facts, farm inputs
A22: FixedCost | B22: 20000 | C22: $ per season | D22: Case facts, farm inputs
A23: OwnHours | B23: 720 | C23: hours per season | D23: Case facts, farm inputs
A24: OwnRate | B24: =OwnSeasonPay/OwnPayBasisHours -> 34.722222 | C24: $ per hour (implied) | D24: Calculated: OwnSeasonPay ÷ OwnPayBasisHours (the case prints 34.72)
A25: TempRate | B25: =TempSeasonPay/TempHoursEach -> 17.361111 | C25: $ per hour | D25: Calculated: TempSeasonPay ÷ TempHoursEach (the case prints 17.36)
A26: TempHoursEach | B26: 1440 | C26: hours per worker per season | D26: Case facts, farm inputs
A27: MaxTemps | B27: 4 | C27: workers | D27: Case facts, farm inputs
A29: What-if inputs | B29: My own assumptions, not the case's. Used only on the What if tab.
A30: Name | B30: Value | C30: Unit | D30: Source
A31: HourlyLoss | B31: 0.01 | C31: efficiency lost for each hour already worked that day | D31: My assumption
A32: DailyPenalty | B32: 0.01 | C32: efficiency lost at the start of each day, carried until the weekend | D32: My assumption
A33: TempDayHours | B33: 8 | C33: hours per day | D33: 1,440 hours ÷ 36 weeks = 40 hours a week
A34: TempDaysPerWeek | B34: 5 | C34: days | D34: 1,440 hours ÷ 36 weeks = 40 hours a week
A35: OwnDayHours | B35: 4 | C35: hours per day | D35: My choice: 720 hours ÷ 36 weeks = 20 hours a week
A36: OwnDaysPerWeek | B36: 5 | C36: days | D36: My choice: 720 hours ÷ 36 weeks = 20 hours a week
A38: Pay (the givens) | B38: Case facts. OwnRate and TempRate above are worked out from these.
A39: Name | B39: Value | C39: Unit | D39: Source
A40: OwnSeasonPay | B40: 50000 | C40: $ per season | D40: Case facts, farm inputs (the given behind the printed $34.72)
A41: OwnPayBasisHours | B41: 1440 | C41: paid hours per season | D41: Case facts, farm inputs (720 of them are in the field)
A42: TempSeasonPay | B42: 25000 | C42: $ per temp worker per season | D42: Case facts, farm inputs (the given behind the printed $17.36)

Sheet Schedules
A1: Schedules: the cost one extra bed adds, one crop at a time
A2: Each crop is worked out as if it were the only crop planted: my 720 hours go to it first, then temporary hours. Each schedule runs past the crop's cap. Solver does not use this tab.
A3: Last profitable bed within the cap | D3: =_xlfn.MAXIFS(A$9:A$58,H$9:H$58,"Yes",A$9:A$58,"<="&Tomato_Cap) -> 10 | K3: Last profitable bed within the cap | N3: =_xlfn.MAXIFS(K$9:K$58,R$9:R$58,"Yes",K$9:K$58,"<="&Carrot_Cap) -> 20 | U3: Last profitable bed within the cap | X3: =_xlfn.MAXIFS(U$9:U$58,AB$9:AB$58,"Yes",U$9:U$58,"<="&Mesclun_Cap) -> 30
A4: Tomatoes | K4: Carrots | U4: Mescluns
A5: Last profitable bed | D5: =_xlfn.MAXIFS(A$9:A$58,H$9:H$58,"Yes") -> 10 | K5: Last profitable bed | N5: =_xlfn.MAXIFS(K$9:K$58,R$9:R$58,"Yes") -> 26 | U5: Last profitable bed | X5: =_xlfn.MAXIFS(U$9:U$58,AB$9:AB$58,"Yes") -> 37
A6: Fewest beds to cover FixedCost alone | D6: =IF(COUNTIF(I$9:I$58,">=0")=0,"None",_xlfn.MINIFS(A$9:A$58,I$9:I$58,">=0")) -> 7 | K6: Fewest beds to cover FixedCost alone | N6: =IF(COUNTIF(S$9:S$58,">=0")=0,"None",_xlfn.MINIFS(K$9:K$58,S$9:S$58,">=0")) -> None | U6: Fewest beds to cover FixedCost alone | X6: =IF(COUNTIF(AC$9:AC$58,">=0")=0,"None",_xlfn.MINIFS(U$9:U$58,AC$9:AC$58,">=0")) -> None
A7: Bed q | B7: Hours for q beds | C7: Extra hours bed q adds | D7: Labor cost for q beds | E7: Total cost for q beds | F7: Tomato_MC(q) | G7: Revenue per bed | H7: MC at or below revenue? | I7: Profit after FixedCost | K7: Bed q | L7: Hours for q beds | M7: Extra hours bed q adds | N7: Labor cost for q beds | O7: Total cost for q beds | P7: Carrot_MC(q) | Q7: Revenue per bed | R7: MC at or below revenue? | S7: Profit after FixedCost | U7: Bed q | V7: Hours for q beds | W7: Extra hours bed q adds | X7: Labor cost for q beds | Y7: Total cost for q beds | Z7: Mesclun_MC(q) | AA7: Revenue per bed | AB7: MC at or below revenue? | AC7: Profit after FixedCost
A8: 0 | B8: =A8*Tomato_HoursPerWeek*SeasonWeeks*(1+Tomato_DimRate)^A8 -> 0 | D8: =MIN(B8,OwnHours)*OwnRate+MAX(B8-OwnHours,0)*TempRate -> 0 | E8: =D8+A8*Tomato_Fertilizer -> 0 | K8: 0 | L8: =K8*Carrot_HoursPerWeek*SeasonWeeks*(1+Carrot_DimRate)^K8 -> 0 | N8: =MIN(L8,OwnHours)*OwnRate+MAX(L8-OwnHours,0)*TempRate -> 0 | O8: =N8+K8*Carrot_Fertilizer -> 0 | U8: 0 | V8: =U8*Mesclun_HoursPerWeek*SeasonWeeks*(1+Mesclun_DimRate)^U8 -> 0 | X8: =MIN(V8,OwnHours)*OwnRate+MAX(V8-OwnHours,0)*TempRate -> 0 | Y8: =X8+U8*Mesclun_Fertilizer -> 0
A9: 1 | B9: =A9*Tomato_HoursPerWeek*SeasonWeeks*(1+Tomato_DimRate)^A9 -> 99 | C9: =B9-B8 -> 99 | D9: =MIN(B9,OwnHours)*OwnRate+MAX(B9-OwnHours,0)*TempRate -> 3437.5 | E9: =D9+A9*Tomato_Fertilizer -> 4317.5 | F9: =E9-E8 -> 4317.5 | G9: =Tomato_Revenue -> 8800 | H9: =IF(F9<=G9,"Yes","No") -> Yes | I9: =A9*Tomato_Revenue-E9-FixedCost -> -15517.5 | K9: 1 | L9: =K9*Carrot_HoursPerWeek*SeasonWeeks*(1+Carrot_DimRate)^K9 -> 30.75 | M9: =L9-L8 -> 30.75 | N9: =MIN(L9,OwnHours)*OwnRate+MAX(L9-OwnHours,0)*TempRate -> 1067.7083 | O9: =N9+K9*Carrot_Fertilizer -> 1507.7083 | P9: =O9-O8 -> 1507.7083 | Q9: =Carrot_Revenue -> 2094 | R9: =IF(P9<=Q9,"Yes","No") -> Yes | S9: =K9*Carrot_Revenue-O9-FixedCost -> -19413.708 | U9: 1 | V9: =U9*Mesclun_HoursPerWeek*SeasonWeeks*(1+Mesclun_DimRate)^U9 -> 45.5625 | W9: =V9-V8 -> 45.5625 | X9: =MIN(V9,OwnHours)*OwnRate+MAX(V9-OwnHours,0)*TempRate -> 1582.0312 | Y9: =X9+U9*Mesclun_Fertilizer -> 2462.0312 | Z9: =Y9-Y8 -> 2462.0312 | AA9: =Mesclun_Revenue -> 2700 | AB9: =IF(Z9<=AA9,"Yes","No") -> Yes | AC9: =U9*Mesclun_Revenue-Y9-FixedCost -> -19762.031
A10: 2 | B10: =A10*Tomato_HoursPerWeek*SeasonWeeks*(1+Tomato_DimRate)^A10 -> 217.8 | C10: =B10-B9 -> 118.8 | D10: =MIN(B10,OwnHours)*OwnRate+MAX(B10-OwnHours,0)*TempRate -> 7562.5 | E10: =D10+A10*Tomato_Fertilizer -> 9322.5 | F10: =E10-E9 -> 5005 | G10: =Tomato_Revenue -> 8800 | H10: =IF(F10<=G10,"Yes","No") -> Yes | I10: =A10*Tomato_Revenue-E10-FixedCost -> -11722.5 | K10: 2 | L10: =K10*Carrot_HoursPerWeek*SeasonWeeks*(1+Carrot_DimRate)^K10 -> 63.0375 | M10: =L10-L9 -> 32.2875 | N10: =MIN(L10,OwnHours)*OwnRate+MAX(L10-OwnHours,0)*TempRate -> 2188.8021 | O10: =N10+K10*Carrot_Fertilizer -> 3068.8021 | P10: =O10-O9 -> 1561.0937 | Q10: =Carrot_Revenue -> 2094 | R10: =IF(P10<=Q10,"Yes","No") -> Yes | S10: =K10*Carrot_Revenue-O10-FixedCost -> -18880.802 | U10: 2 | V10: =U10*Mesclun_HoursPerWeek*SeasonWeeks*(1+Mesclun_DimRate)^U10 -> 92.264062 | W10: =V10-V9 -> 46.701562 | X10: =MIN(V10,OwnHours)*OwnRate+MAX(V10-OwnHours,0)*TempRate -> 3203.6133 | Y10: =X10+U10*Mesclun_Fertilizer -> 4963.6133 | Z10: =Y10-Y9 -> 2501.582 | AA10: =Mesclun_Revenue -> 2700 | AB10: =IF(Z10<=AA10,"Yes","No") -> Yes | AC10: =U10*Mesclun_Revenue-Y10-FixedCost -> -19563.613
A11: 3 | B11: =A11*Tomato_HoursPerWeek*SeasonWeeks*(1+Tomato_DimRate)^A11 -> 359.37 | C11: =B11-B10 -> 141.57 | D11: =MIN(B11,OwnHours)*OwnRate+MAX(B11-OwnHours,0)*TempRate -> 12478.125 | E11: =D11+A11*Tomato_Fertilizer -> 15118.125 | F11: =E11-E10 -> 5795.625 | G11: =Tomato_Revenue -> 8800 | H11: =IF(F11<=G11,"Yes","No") -> Yes | I11: =A11*Tomato_Revenue-E11-FixedCost -> -8718.125 | K11: 3 | L11: =K11*Carrot_HoursPerWeek*SeasonWeeks*(1+Carrot_DimRate)^K11 -> 96.920156 | M11: =L11-L10 -> 33.882656 | N11: =MIN(L11,OwnHours)*OwnRate+MAX(L11-OwnHours,0)*TempRate -> 3365.2832 | O11: =N11+K11*Carrot_Fertilizer -> 4685.2832 | P11: =O11-O10 -> 1616.4811 | Q11: =Carrot_Revenue -> 2094 | R11: =IF(P11<=Q11,"Yes","No") -> Yes | S11: =K11*Carrot_Revenue-O11-FixedCost -> -18403.283 | U11: 3 | V11: =U11*Mesclun_HoursPerWeek*SeasonWeeks*(1+Mesclun_DimRate)^U11 -> 140.12604 | W11: =V11-V10 -> 47.861982 | X11: =MIN(V11,OwnHours)*OwnRate+MAX(V11-OwnHours,0)*TempRate -> 4865.4877 | Y11: =X11+U11*Mesclun_Fertilizer -> 7505.4877 | Z11: =Y11-Y10 -> 2541.8744 | AA11: =Mesclun_Revenue -> 2700 | AB11: =IF(Z11<=AA11,"Yes","No") -> Yes | AC11: =U11*Mesclun_Revenue-Y11-FixedCost -> -19405.488
A12: 4 | B12: =A12*Tomato_HoursPerWeek*SeasonWeeks*(1+Tomato_DimRate)^A12 -> 527.076 | C12: =B12-B11 -> 167.706 | D12: =MIN(B12,OwnHours)*OwnRate+MAX(B12-OwnHours,0)*TempRate -> 18301.25 | E12: =D12+A12*Tomato_Fertilizer -> 21821.25 | F12: =E12-E11 -> 6703.125 | G12: =Tomato_Revenue -> 8800 | H12: =IF(F12<=G12,"Yes","No") -> Yes | I12: =A12*Tomato_Revenue-E12-FixedCost -> -6621.25 | K12: 4 | L12: =K12*Carrot_HoursPerWeek*SeasonWeeks*(1+Carrot_DimRate)^K12 -> 132.45755 | M12: =L12-L11 -> 35.537391 | N12: =MIN(L12,OwnHours)*OwnRate+MAX(L12-OwnHours,0)*TempRate -> 4599.2204 | O12: =N12+K12*Carrot_Fertilizer -> 6359.2204 | P12: =O12-O11 -> 1673.9372 | Q12: =Carrot_Revenue -> 2094 | R12: =IF(P12<=Q12,"Yes","No") -> Yes | S12: =K12*Carrot_Revenue-O12-FixedCost -> -17983.22 | U12: 4 | V12: =U12*Mesclun_HoursPerWeek*SeasonWeeks*(1+Mesclun_DimRate)^U12 -> 189.17016 | W12: =V12-V11 -> 49.044116 | X12: =MIN(V12,OwnHours)*OwnRate+MAX(V12-OwnHours,0)*TempRate -> 6568.4084 | Y12: =X12+U12*Mesclun_Fertilizer -> 10088.408 | Z12: =Y12-Y11 -> 2582.9207 | AA12: =Mesclun_Revenue -> 2700 | AB12: =IF(Z12<=AA12,"Yes","No") -> Yes | AC12: =U12*Mesclun_Revenue-Y12-FixedCost -> -19288.408
A13: 5 | B13: =A13*Tomato_HoursPerWeek*SeasonWeeks*(1+Tomato_DimRate)^A13 -> 724.7295 | C13: =B13-B12 -> 197.6535 | D13: =MIN(B13,OwnHours)*OwnRate+MAX(B13-OwnHours,0)*TempRate -> 25082.109 | E13: =D13+A13*Tomato_Fertilizer -> 29482.109 | F13: =E13-E12 -> 7660.8594 | G13: =Tomato_Revenue -> 8800 | H13: =IF(F13<=G13,"Yes","No") -> Yes | I13: =A13*Tomato_Revenue-E13-FixedCost -> -5482.1094 | K13: 5 | L13: =K13*Carrot_HoursPerWeek*SeasonWeeks*(1+Carrot_DimRate)^K13 -> 169.71123 | M13: =L13-L12 -> 37.253685 | N13: =MIN(L13,OwnHours)*OwnRate+MAX(L13-OwnHours,0)*TempRate -> 5892.7511 | O13: =N13+K13*Carrot_Fertilizer -> 8092.7511 | P13: =O13-O12 -> 1733.5307 | Q13: =Carrot_Revenue -> 2094 | R13: =IF(P13<=Q13,"Yes","No") -> Yes | S13: =K13*Carrot_Revenue-O13-FixedCost -> -17622.751 | U13: 5 | V13: =U13*Mesclun_HoursPerWeek*SeasonWeeks*(1+Mesclun_DimRate)^U13 -> 239.41848 | W13: =V13-V12 -> 50.248324 | X13: =MIN(V13,OwnHours)*OwnRate+MAX(V13-OwnHours,0)*TempRate -> 8313.1418 | Y13: =X13+U13*Mesclun_Fertilizer -> 12713.142 | Z13: =Y13-Y12 -> 2624.7335 | AA13: =Mesclun_Revenue -> 2700 | AB13: =IF(Z13<=AA13,"Yes","No") -> Yes | AC13: =U13*Mesclun_Revenue-Y13-FixedCost -> -19213.142
A14: 6 | B14: =A14*Tomato_HoursPerWeek*SeasonWeeks*(1+Tomato_DimRate)^A14 -> 956.64294 | C14: =B14-B13 -> 231.91344 | D14: =MIN(B14,OwnHours)*OwnRate+MAX(B14-OwnHours,0)*TempRate -> 29108.384 | E14: =D14+A14*Tomato_Fertilizer -> 34388.384 | F14: =E14-E13 -> 4906.275 | G14: =Tomato_Revenue -> 8800 | H14: =IF(F14<=G14,"Yes","No") -> Yes | I14: =A14*Tomato_Revenue-E14-FixedCost -> -1588.3844 | K14: 6 | L14: =K14*Carrot_HoursPerWeek*SeasonWeeks*(1+Carrot_DimRate)^K14 -> 208.74482 | M14: =L14-L13 -> 39.033583 | N14: =MIN(L14,OwnHours)*OwnRate+MAX(L14-OwnHours,0)*TempRate -> 7248.0839 | O14: =N14+K14*Carrot_Fertilizer -> 9888.0839 | P14: =O14-O13 -> 1795.3328 | Q14: =Carrot_Revenue -> 2094 | R14: =IF(P14<=Q14,"Yes","No") -> Yes | S14: =K14*Carrot_Revenue-O14-FixedCost -> -17324.084 | U14: 6 | V14: =U14*Mesclun_HoursPerWeek*SeasonWeeks*(1+Mesclun_DimRate)^U14 -> 290.89346 | W14: =V14-V13 -> 51.474974 | X14: =MIN(V14,OwnHours)*OwnRate+MAX(V14-OwnHours,0)*TempRate -> 10100.467 | Y14: =X14+U14*Mesclun_Fertilizer -> 15380.467 | Z14: =Y14-Y13 -> 2667.3255 | AA14: =Mesclun_Revenue -> 2700 | AB14: =IF(Z14<=AA14,"Yes","No") -> Yes | AC14: =U14*Mesclun_Revenue-Y14-FixedCost -> -19180.467
A15: 7 | B15: =A15*Tomato_HoursPerWeek*SeasonWeeks*(1+Tomato_DimRate)^A15 -> 1227.6918 | C15: =B15-B14 -> 271.04883 | D15: =MIN(B15,OwnHours)*OwnRate+MAX(B15-OwnHours,0)*TempRate -> 33814.093 | E15: =D15+A15*Tomato_Fertilizer -> 39974.093 | F15: =E15-E14 -> 5585.7089 | G15: =Tomato_Revenue -> 8800 | H15: =IF(F15<=G15,"Yes","No") -> Yes | I15: =A15*Tomato_Revenue-E15-FixedCost -> 1625.9067 | K15: 7 | L15: =K15*Carrot_HoursPerWeek*SeasonWeeks*(1+Carrot_DimRate)^K15 -> 249.62401 | M15: =L15-L14 -> 40.879193 | N15: =MIN(L15,OwnHours)*OwnRate+MAX(L15-OwnHours,0)*TempRate -> 8667.5003 | O15: =N15+K15*Carrot_Fertilizer -> 11747.5 | P15: =O15-O14 -> 1859.4164 | Q15: =Carrot_Revenue -> 2094 | R15: =IF(P15<=Q15,"Yes","No") -> Yes | S15: =K15*Carrot_Revenue-O15-FixedCost -> -17089.5 | U15: 7 | V15: =U15*Mesclun_HoursPerWeek*SeasonWeeks*(1+Mesclun_DimRate)^U15 -> 343.6179 | W15: =V15-V14 -> 52.724439 | X15: =MIN(V15,OwnHours)*OwnRate+MAX(V15-OwnHours,0)*TempRate -> 11931.177 | Y15: =X15+U15*Mesclun_Fertilizer -> 18091.177 | Z15: =Y15-Y14 -> 2710.7097 | AA15: =Mesclun_Revenue -> 2700 | AB15: =IF(Z15<=AA15,"Yes","No") -> No | AC15: =U15*Mesclun_Revenue-Y15-FixedCost -> -19191.177
A16: 8 | B16: =A16*Tomato_HoursPerWeek*SeasonWeeks*(1+Tomato_DimRate)^A16 -> 1543.3839 | C16: =B16-B15 -> 315.69217 | D16: =MIN(B16,OwnHours)*OwnRate+MAX(B16-OwnHours,0)*TempRate -> 39294.86 | E16: =D16+A16*Tomato_Fertilizer -> 46334.86 | F16: =E16-E15 -> 6360.7668 | G16: =Tomato_Revenue -> 8800 | H16: =IF(F16<=G16,"Yes","No") -> Yes | I16: =A16*Tomato_Revenue-E16-FixedCost -> 4065.1399 | K16: 8 | L16: =K16*Carrot_HoursPerWeek*SeasonWeeks*(1+Carrot_DimRate)^K16 -> 292.4167 | M16: =L16-L15 -> 42.792687 | N16: =MIN(L16,OwnHours)*OwnRate+MAX(L16-OwnHours,0)*TempRate -> 10153.357 | O16: =N16+K16*Carrot_Fertilizer -> 13673.357 | P16: =O16-O15 -> 1925.8572 | Q16: =Carrot_Revenue -> 2094 | R16: =IF(P16<=Q16,"Yes","No") -> Yes | S16: =K16*Carrot_Revenue-O16-FixedCost -> -16921.357 | U16: 8 | V16: =U16*Mesclun_HoursPerWeek*SeasonWeeks*(1+Mesclun_DimRate)^U16 -> 397.615 | W16: =V16-V15 -> 53.997098 | X16: =MIN(V16,OwnHours)*OwnRate+MAX(V16-OwnHours,0)*TempRate -> 13806.076 | Y16: =X16+U16*Mesclun_Fertilizer -> 20846.076 | Z16: =Y16-Y15 -> 2754.8992 | AA16: =Mesclun_Revenue -> 2700 | AB16: =IF(Z16<=AA16,"Yes","No") -> No | AC16: =U16*Mesclun_Revenue-Y16-FixedCost -> -19246.076
A17: 9 | B17: =A17*Tomato_HoursPerWeek*SeasonWeeks*(1+Tomato_DimRate)^A17 -> 1909.9376 | C17: =B17-B16 -> 366.55369 | D17: =MIN(B17,OwnHours)*OwnRate+MAX(B17-OwnHours,0)*TempRate -> 45658.639 | E17: =D17+A17*Tomato_Fertilizer -> 53578.639 | F17: =E17-E16 -> 7243.7793 | G17: =Tomato_Revenue -> 8800 | H17: =IF(F17<=G17,"Yes","No") -> Yes | I17: =A17*Tomato_Revenue-E17-FixedCost -> 5621.3606 | K17: 9 | L17: =K17*Carrot_HoursPerWeek*SeasonWeeks*(1+Carrot_DimRate)^K17 -> 337.193 | M17: =L17-L16 -> 44.776306 | N17: =MIN(L17,OwnHours)*OwnRate+MAX(L17-OwnHours,0)*TempRate -> 11708.09 | O17: =N17+K17*Carrot_Fertilizer -> 15668.09 | P17: =O17-O16 -> 1994.7329 | Q17: =Carrot_Revenue -> 2094 | R17: =IF(P17<=Q17,"Yes","No") -> Yes | S17: =K17*Carrot_Revenue-O17-FixedCost -> -16822.09 | U17: 9 | V17: =U17*Mesclun_HoursPerWeek*SeasonWeeks*(1+Mesclun_DimRate)^U17 -> 452.90833 | W17: =V17-V16 -> 55.293335 | X17: =MIN(V17,OwnHours)*OwnRate+MAX(V17-OwnHours,0)*TempRate -> 15725.984 | Y17: =X17+U17*Mesclun_Fertilizer -> 23645.984 | Z17: =Y17-Y16 -> 2799.9075 | AA17: =Mesclun_Revenue -> 2700 | AB17: =IF(Z17<=AA17,"Yes","No") -> No | AC17: =U17*Mesclun_Revenue-Y17-FixedCost -> -19345.984
A18: 10 | B18: =A18*Tomato_HoursPerWeek*SeasonWeeks*(1+Tomato_DimRate)^A18 -> 2334.3682 | C18: =B18-B17 -> 424.43058 | D18: =MIN(B18,OwnHours)*OwnRate+MAX(B18-OwnHours,0)*TempRate -> 53027.226 | E18: =D18+A18*Tomato_Fertilizer -> 61827.226 | F18: =E18-E17 -> 8248.5865 | G18: =Tomato_Revenue -> 8800 | H18: =IF(F18<=G18,"Yes","No") -> Yes | I18: =A18*Tomato_Revenue-E18-FixedCost -> 6172.7741 | K18: 10 | L18: =K18*Carrot_HoursPerWeek*SeasonWeeks*(1+Carrot_DimRate)^K18 -> 384.02536 | M18: =L18-L17 -> 46.832361 | N18: =MIN(L18,OwnHours)*OwnRate+MAX(L18-OwnHours,0)*TempRate -> 13334.214 | O18: =N18+K18*Carrot_Fertilizer -> 17734.214 | P18: =O18-O17 -> 2066.1237 | Q18: =Carrot_Revenue -> 2094 | R18: =IF(P18<=Q18,"Yes","No") -> Yes | S18: =K18*Carrot_Revenue-O18-FixedCost -> -16794.214 | U18: 10 | V18: =U18*Mesclun_HoursPerWeek*SeasonWeeks*(1+Mesclun_DimRate)^U18 -> 509.52187 | W18: =V18-V17 -> 56.613541 | X18: =MIN(V18,OwnHours)*OwnRate+MAX(V18-OwnHours,0)*TempRate -> 17691.732 | Y18: =X18+U18*Mesclun_Fertilizer -> 26491.732 | Z18: =Y18-Y17 -> 2845.748 | AA18: =Mesclun_Revenue -> 2700 | AB18: =IF(Z18<=AA18,"Yes","No") -> No | AC18: =U18*Mesclun_Revenue-Y18-FixedCost -> -19491.732
A19: 11 | B19: =A19*Tomato_HoursPerWeek*SeasonWeeks*(1+Tomato_DimRate)^A19 -> 2824.5855 | C19: =B19-B18 -> 490.21732 | D19: =MIN(B19,OwnHours)*OwnRate+MAX(B19-OwnHours,0)*TempRate -> 61537.943 | E19: =D19+A19*Tomato_Fertilizer -> 71217.943 | F19: =E19-E18 -> 9390.7174 | G19: =Tomato_Revenue -> 8800 | H19: =IF(F19<=G19,"Yes","No") -> No | I19: =A19*Tomato_Revenue-E19-FixedCost -> 5582.0566 | K19: 11 | L19: =K19*Carrot_HoursPerWeek*SeasonWeeks*(1+Carrot_DimRate)^K19 -> 432.9886 | M19: =L19-L18 -> 48.963234 | N19: =MIN(L19,OwnHours)*OwnRate+MAX(L19-OwnHours,0)*TempRate -> 15034.326 | O19: =N19+K19*Carrot_Fertilizer -> 19874.326 | P19: =O19-O18 -> 2140.1123 | Q19: =Carrot_Revenue -> 2094 | R19: =IF(P19<=Q19,"Yes","No") -> No | S19: =K19*Carrot_Revenue-O19-FixedCost -> -16840.326 | U19: 11 | V19: =U19*Mesclun_HoursPerWeek*SeasonWeeks*(1+Mesclun_DimRate)^U19 -> 567.47999 | W19: =V19-V18 -> 57.958113 | X19: =MIN(V19,OwnHours)*OwnRate+MAX(V19-OwnHours,0)*TempRate -> 19704.166 | Y19: =X19+U19*Mesclun_Fertilizer -> 29384.166 | Z19: =Y19-Y18 -> 2892.4345 | AA19: =Mesclun_Revenue -> 2700 | AB19: =IF(Z19<=AA19,"Yes","No") -> No | AC19: =U19*Mesclun_Revenue-Y19-FixedCost -> -19684.166
A20: 12 | B20: =A20*Tomato_HoursPerWeek*SeasonWeeks*(1+Tomato_DimRate)^A20 -> 3389.5026 | C20: =B20-B19 -> 564.91711 | D20: =MIN(B20,OwnHours)*OwnRate+MAX(B20-OwnHours,0)*TempRate -> 71345.532 | E20: =D20+A20*Tomato_Fertilizer -> 81905.532 | F20: =E20-E19 -> 10687.589 | G20: =Tomato_Revenue -> 8800 | H20: =IF(F20<=G20,"Yes","No") -> No | I20: =A20*Tomato_Revenue-E20-FixedCost -> 3694.4679 | K20: 12 | L20: =K20*Carrot_HoursPerWeek*SeasonWeeks*(1+Carrot_DimRate)^K20 -> 484.15998 | M20: =L20-L19 -> 51.17138 | N20: =MIN(L20,OwnHours)*OwnRate+MAX(L20-OwnHours,0)*TempRate -> 16811.11 | O20: =N20+K20*Carrot_Fertilizer -> 22091.11 | P20: =O20-O19 -> 2216.784 | Q20: =Carrot_Revenue -> 2094 | R20: =IF(P20<=Q20,"Yes","No") -> No | S20: =K20*Carrot_Revenue-O20-FixedCost -> -16963.11 | U20: 12 | V20: =U20*Mesclun_HoursPerWeek*SeasonWeeks*(1+Mesclun_DimRate)^U20 -> 626.80744 | W20: =V20-V19 -> 59.327453 | X20: =MIN(V20,OwnHours)*OwnRate+MAX(V20-OwnHours,0)*TempRate -> 21764.147 | Y20: =X20+U20*Mesclun_Fertilizer -> 32324.147 | Z20: =Y20-Y19 -> 2939.981 | AA20: =Mesclun_Revenue -> 2700 | AB20: =IF(Z20<=AA20,"Yes","No") -> No | AC20: =U20*Mesclun_Revenue-Y20-FixedCost -> -19924.147
... A58: 50 | B58: =A58*Tomato_HoursPerWeek*SeasonWeeks*(1+Tomato_DimRate)^A58 -> 528258.84 | C58: =B58-B57 -> 57628.237 | D58: =MIN(B58,OwnHours)*OwnRate+MAX(B58-OwnHours,0)*TempRate -> 9183660.4 | E58: =D58+A58*Tomato_Fertilizer -> 9227660.4 | F58: =E58-E57 -> 1001370.2 | G58: =Tomato_Revenue -> 8800 | H58: =IF(F58<=G58,"Yes","No") -> No | I58: =A58*Tomato_Revenue-E58-FixedCost -> -8807660.4 | K58: 50 | L58: =K58*Carrot_HoursPerWeek*SeasonWeeks*(1+Carrot_DimRate)^K58 -> 5155.6631 | M58: =L58-L57 -> 226.34618 | N58: =MIN(L58,OwnHours)*OwnRate+MAX(L58-OwnHours,0)*TempRate -> 102008.04 | O58: =N58+K58*Carrot_Fertilizer -> 124008.04 | P58: =O58-O57 -> 4369.6212 | Q58: =Carrot_Revenue -> 2094 | R58: =IF(P58<=Q58,"Yes","No") -> No | S58: =K58*Carrot_Revenue-O58-FixedCost -> -39308.04 | U58: 50 | V58: =U58*Mesclun_HoursPerWeek*SeasonWeeks*(1+Mesclun_DimRate)^U58 -> 4187.3003 | W58: =V58-V57 -> 134.40717 | X58: =MIN(V58,OwnHours)*OwnRate+MAX(V58-OwnHours,0)*TempRate -> 85196.186 | Y58: =X58+U58*Mesclun_Fertilizer -> 129196.19 | Z58: =Y58-Y57 -> 3213.4578 | AA58: =Mesclun_Revenue -> 2700 | AB58: =IF(Z58<=AA58,"Yes","No") -> No | AC58: =U58*Mesclun_Revenue-Y58-FixedCost -> -14196.186
A60: Bold row: the crop's bed cap. Green: marginal cost is at or below revenue per bed.

Sheet Answer Report 1
A1: Microsoft Excel 16.112 Answer Report
A2: Worksheet: [model.xlsx]Optimizer
A3: Report Created: 10/27/26 4:14:01 PM
A4: Result: Solver found a solution. All constraints and optimality conditions are satisfied.
A5: Solver Engine
B6: Engine: GRG Nonlinear
B7: Solution Time: 820.187 Seconds.
B8: Iterations: 0 Subproblems: 2
A9: Solver Options
B10: Max Time Unlimited, Iterations Unlimited, Precision 0.000001, Use Automatic Scaling
B11: Convergence 0.0001, Population Size 100, Random Seed 0, Derivatives Forward, Require Bounds
B12: Max Subproblems Unlimited, Max Integer Sols Unlimited, Integer Tolerance 0%, Assume NonNegative
A14: Objective Cell (Max)
B15: Cell | C15: Name | D15: Original Value | E15: Final Value
B16: $B$19 | C16: SeasonProfit | D16: -20000 | E16: 42775.155
A19: Variable Cells
B20: Cell | C20: Name | D20: Original Value | E20: Final Value | F20: Integer
B21: $B$6 | C21: Tomato_Beds | D21: 0 | E21: 10 | F21: Integer
B22: $B$7 | C22: Carrot_Beds | D22: 0 | E22: 20 | F22: Integer
B23: $B$8 | C23: Mesclun_Beds | D23: 0 | E23: 30 | F23: Integer
A26: Constraints
B27: Cell | C27: Name | D27: Cell Value | E27: Formula | F27: Status | G27: Slack
B28: $B$17 | C28: BedsPlanted | D28: 60 | E28: $B$17<=$F$16 | F28: Not Binding | G28: 4
B29: $B$13 | C29: TempHours | D29: 4556.8228 | E29: $B$13<=$B$14 | F29: Not Binding | G29: 1203.1772
B30: $B$7 | C30: Carrot_Beds | D30: 20 | E30: $B$7<=$F$14 | F30: Binding | G30: 0
B31: $B$8 | C31: Mesclun_Beds | D31: 30 | E31: $B$8<=$F$15 | F31: Binding | G31: 0
B32: $B$6 | C32: Tomato_Beds | D32: 10 | E32: $B$6<=$F$13 | F32: Binding | G32: 0
B33: $B$6:$B$8=Integer

Sheet Answer Report 2
A1: Microsoft Excel 16.112 Answer Report
A2: Worksheet: [model.xlsx]Optimizer
A3: Report Created: 10/27/26 4:15:35 PM
A4: Result: Solver found a solution. All constraints and optimality conditions are satisfied.
A5: Solver Engine
B6: Engine: GRG Nonlinear
B7: Solution Time: 938.842 Seconds.
B8: Iterations: 0 Subproblems: 2
A9: Solver Options
B10: Max Time Unlimited, Iterations Unlimited, Precision 0.000001, Use Automatic Scaling
B11: Convergence 0.0001, Population Size 100, Random Seed 0, Derivatives Forward, Require Bounds
B12: Max Subproblems Unlimited, Max Integer Sols Unlimited, Integer Tolerance 0%, Assume NonNegative
A14: Objective Cell (Max)
B15: Cell | C15: Name | D15: Original Value | E15: Final Value
B16: $B$19 | C16: SeasonProfit | D16: -84320.118 | E16: 42775.155
A19: Variable Cells
B20: Cell | C20: Name | D20: Original Value | E20: Final Value | F20: Integer
B21: $B$6 | C21: Tomato_Beds | D21: 20 | E21: 10 | F21: Integer
B22: $B$7 | C22: Carrot_Beds | D22: 0 | E22: 20 | F22: Integer
B23: $B$8 | C23: Mesclun_Beds | D23: 0 | E23: 30 | F23: Integer
A26: Constraints
B27: Cell | C27: Name | D27: Cell Value | E27: Formula | F27: Status | G27: Slack
B28: $B$17 | C28: BedsPlanted | D28: 60 | E28: $B$17<=$F$16 | F28: Not Binding | G28: 4
B29: $B$13 | C29: TempHours | D29: 4556.8228 | E29: $B$13<=$B$14 | F29: Not Binding | G29: 1203.1772
B30: $B$7 | C30: Carrot_Beds | D30: 20 | E30: $B$7<=$F$14 | F30: Binding | G30: 0
B31: $B$8 | C31: Mesclun_Beds | D31: 30 | E31: $B$8<=$F$15 | F31: Binding | G31: 0
B32: $B$6 | C32: Tomato_Beds | D32: 10 | E32: $B$6<=$F$13 | F32: Binding | G32: 0
B33: $B$6:$B$8=Integer

Sheet Answer Report 4
A1: Microsoft Excel 16.112 Answer Report
A2: Worksheet: [model.xlsx]Optimizer
A3: Report Created: 10/29/26 5:58:33 PM
A4: Result: Solver found a solution. All constraints and optimality conditions are satisfied.
A5: Solver Engine
B6: Engine: GRG Nonlinear
B7: Solution Time: 1524.107 Seconds.
B8: Iterations: 0 Subproblems: 2
A9: Solver Options
B10: Max Time Unlimited, Iterations Unlimited, Precision 1E-06, Use Automatic Scaling
B11: Convergence 0.0001, Population Size 100, Random Seed 0, Derivatives Forward, Require Bounds
B12: Max Subproblems Unlimited, Max Integer Sols Unlimited, Integer Tolerance 1%, Assume NonNegative
A14: Objective Cell (Max)
B15: Cell | C15: Name | D15: Original Value | E15: Final Value
B16: $B$19 | C16: SeasonProfit | D16: -20000 | E16: 42761.665
A19: Variable Cells
B20: Cell | C20: Name | D20: Original Value | E20: Final Value | F20: Integer
B21: $B$6 | C21: Tomato_Beds | D21: 0 | E21: 10 | F21: Integer
B22: $B$7 | C22: Carrot_Beds | D22: 0 | E22: 20 | F22: Integer
B23: $B$8 | C23: Mesclun_Beds | D23: 0 | E23: 30 | F23: Integer
A26: Constraints
B27: Cell | C27: Name | D27: Cell Value | E27: Formula | F27: Status | G27: Slack
B28: $B$17 | C28: BedsPlanted | D28: 60 | E28: $B$17<=$F$16 | F28: Not Binding | G28: 4
B29: $B$13 | C29: TempHours | D29: 4557.2161 | E29: $B$13<=$B$14 | F29: Not Binding | G29: 1202.7839
B30: $B$7 | C30: Carrot_Beds | D30: 20 | E30: $B$7<=$F$14 | F30: Binding | G30: 0
B31: $B$8 | C31: Mesclun_Beds | D31: 30 | E31: $B$8<=$F$15 | F31: Binding | G31: 0
B32: $B$6 | C32: Tomato_Beds | D32: 10 | E32: $B$6<=$F$13 | F32: Binding | G32: 0
B33: $B$6:$B$8=Integer

Sheet Answer Report 5
A1: Microsoft Excel 16.112 Answer Report
A2: Worksheet: [model.xlsx]Optimizer
A3: Report Created: 10/29/26 5:59:32 PM
A4: Result: Solver found a solution. All constraints and optimality conditions are satisfied.
A5: Solver Engine
B6: Engine: GRG Nonlinear
B7: Solution Time: 1483.533 Seconds.
B8: Iterations: 0 Subproblems: 2
A9: Solver Options
B10: Max Time Unlimited, Iterations Unlimited, Precision 0.000001, Use Automatic Scaling
B11: Convergence 0.0001, Population Size 100, Random Seed 0, Derivatives Forward, Require Bounds
B12: Max Subproblems Unlimited, Max Integer Sols Unlimited, Integer Tolerance 1%, Assume NonNegative
A14: Objective Cell (Max)
B15: Cell | C15: Name | D15: Original Value | E15: Final Value
B16: $B$19 | C16: SeasonProfit | D16: -84334.373 | E16: 42761.665
A19: Variable Cells
B20: Cell | C20: Name | D20: Original Value | E20: Final Value | F20: Integer
B21: $B$6 | C21: Tomato_Beds | D21: 20 | E21: 10 | F21: Integer
B22: $B$7 | C22: Carrot_Beds | D22: 0 | E22: 20 | F22: Integer
B23: $B$8 | C23: Mesclun_Beds | D23: 0 | E23: 30 | F23: Integer
A26: Constraints
B27: Cell | C27: Name | D27: Cell Value | E27: Formula | F27: Status | G27: Slack
B28: $B$17 | C28: BedsPlanted | D28: 60 | E28: $B$17<=$F$16 | F28: Not Binding | G28: 4
B29: $B$13 | C29: TempHours | D29: 4557.2161 | E29: $B$13<=$B$14 | F29: Not Binding | G29: 1202.7839
B30: $B$7 | C30: Carrot_Beds | D30: 20 | E30: $B$7<=$F$14 | F30: Binding | G30: 0
B31: $B$8 | C31: Mesclun_Beds | D31: 30 | E31: $B$8<=$F$15 | F31: Binding | G31: 0
B32: $B$6 | C32: Tomato_Beds | D32: 10 | E32: $B$6<=$F$13 | F32: Binding | G32: 0
B33: $B$6:$B$8=Integer

Sheet Answer Report 6
A1: Microsoft Excel 16.112 Answer Report
A2: Worksheet: [model.xlsx]Optimizer
A3: Report Created: 10/29/26 6:09:18 PM
A4: Result: Solver found a solution. All constraints and optimality conditions are satisfied.
A5: Solver Engine
B6: Engine: GRG Nonlinear
B7: Solution Time: 2061.059 Seconds.
B8: Iterations: 6 Subproblems: 2
A9: Solver Options
B10: Max Time Unlimited, Iterations Unlimited, Precision 1E-06, Use Automatic Scaling
B11: Convergence 0.0001, Population Size 100, Random Seed 0, Derivatives Forward, Require Bounds
B12: Max Subproblems Unlimited, Max Integer Sols Unlimited, Integer Tolerance 1%, Assume NonNegative
A14: Objective Cell (Min)
B15: Cell | C15: Name | D15: Original Value | E15: Final Value
B16: $B$45 | C16: BreakEvenBeds | D16: 60 | E16: 7
A19: Variable Cells
B20: Cell | C20: Name | D20: Original Value | E20: Final Value | F20: Integer
B21: $B$31 | C21: BreakEven_Tomato_Beds | D21: 10 | E21: 7 | F21: Integer
B22: $B$32 | C22: BreakEven_Carrot_Beds | D22: 20 | E22: 0 | F22: Integer
B23: $B$33 | C23: BreakEven_Mesclun_Beds | D23: 30 | E23: 0 | F23: Integer
A26: Constraints
B27: Cell | C27: Name | D27: Cell Value | E27: Formula | F27: Status | G27: Slack
B28: $B$42 | C28: BreakEven_BedsPlanted | D28: 7 | E28: $B$42<=$F$16 | F28: Not Binding | G28: 57
B29: $B$44 | C29: BreakEven_SeasonProfit | D29: 1625.9067 | E29: $B$44>=0 | F29: Not Binding | G29: 1625.9067
B30: $B$38 | C30: BreakEven_TempHours | D30: 507.69177 | E30: $B$38<=$B$39 | F30: Not Binding | G30: 5252.3082
B31: $B$32 | C31: BreakEven_Carrot_Beds | D31: 0 | E31: $B$32<=$F$14 | F31: Not Binding | G31: 20
B32: $B$33 | C32: BreakEven_Mesclun_Beds | D32: 0 | E32: $B$33<=$F$15 | F32: Not Binding | G32: 30
B33: $B$31 | C33: BreakEven_Tomato_Beds | D33: 7 | E33: $B$31<=$F$13 | F33: Not Binding | G33: 13
B34: $B$31:$B$33=Integer

Sheet Optimizer
A1: Optimizer: the whole farm
A2: Solver changes the yellow bed counts. Everything else is a formula. Labor is costed for the whole farm, then charged to each crop at the blended rate.
A4: Setup 1: most profit | I4: Solver setup 1: most profit
A5: Crop | B5: Beds | C5: Hours | D5: Revenue | E5: Fertilizer | F5: Labor cost | G5: Crop profit | I5: Set Objective | J5: SeasonProfit (cell B19)
A6: Tomato | B6: 10 | C6: =Tomato_Beds*Tomato_HoursPerWeek*SeasonWeeks*(1+Tomato_DimRate)^Tomato_Beds -> 2334.3682 | D6: =Tomato_Beds*Tomato_Revenue -> 88000 | E6: =Tomato_Beds*Tomato_Fertilizer -> 8800 | F6: =C6*BlendedRate -> 46056.581 | G6: =D6-E6-F6 -> 33143.419 | I6: To | J6: Max
A7: Carrot | B7: 20 | C7: =Carrot_Beds*Carrot_HoursPerWeek*SeasonWeeks*(1+Carrot_DimRate)^Carrot_Beds -> 983.16986 | D7: =Carrot_Beds*Carrot_Revenue -> 41880 | E7: =Carrot_Beds*Carrot_Fertilizer -> 8800 | F7: =C7*BlendedRate -> 19397.729 | G7: =D7-E7-F7 -> 13682.271 | I7: By Changing Variable Cells | J7: B6:B8 (Tomato_Beds, Carrot_Beds, Mesclun_Beds)
A8: Mesclun | B8: 30 | C8: =Mesclun_Beds*Mesclun_HoursPerWeek*SeasonWeeks*(1+Mesclun_DimRate)^Mesclun_Beds -> 1959.678 | D8: =Mesclun_Beds*Mesclun_Revenue -> 81000 | E8: =Mesclun_Beds*Mesclun_Fertilizer -> 26400 | F8: =C8*BlendedRate -> 38664.025 | G8: =D8-E8-F8 -> 15935.975 | I8: Constraint | J8: B6:B8 = integer
A9: Total | B9: =SUM(B6:B8) -> 60 | C9: =SUM(C6:C8) -> 5277.2161 | D9: =SUM(D6:D8) -> 210880 | E9: =SUM(E6:E8) -> 44000 | F9: =SUM(F6:F8) -> 104118.34 | G9: =SUM(G6:G8) -> 62761.665 | I9: Constraint | J9: B6 <= F13 (tomato cap)
I10: Constraint | J10: B7 <= F14 (carrot cap)
A11: TotalHours | B11: =SUM(C6:C8) -> 5277.2161 | C11: Tomato + carrot + mesclun hours | E11: Limits Solver uses | I11: Constraint | J11: B8 <= F15 (mesclun cap)
A12: OwnHoursUsed | B12: =MIN(TotalHours,OwnHours) -> 720 | C12: The smaller of TotalHours and OwnHours | E12: Copied from Inputs, so Solver never reads another tab | I12: Constraint | J12: BedsPlanted <= F16 (total beds)
A13: TempHours | B13: =TotalHours-OwnHoursUsed -> 4557.2161 | C13: Solver keeps this at or below TempHoursMax | E13: Tomato cap | F13: =Tomato_Cap -> 20 | I13: Constraint | J13: TempHours <= TempHoursMax
A14: TempHoursMax | B14: =MaxTemps*TempHoursEach -> 5760 | C14: MaxTemps × TempHoursEach | E14: Carrot cap | F14: =Carrot_Cap -> 20 | I14: Tick | J14: Make Unconstrained Variables Non-Negative (beds are 0 or more)
A15: LaborCost | B15: =OwnHoursUsed*OwnRate+TempHours*TempRate -> 104118.34 | C15: My hours at OwnRate, temp hours at TempRate | E15: Mesclun cap | F15: =Mesclun_Cap -> 30 | I15: Solving Method | J15: GRG Nonlinear
A16: BlendedRate | B16: =IF(TotalHours=0,0,LaborCost/TotalHours) -> 19.729784 | C16: LaborCost ÷ TotalHours (0 when no hours) | E16: Total beds | F16: =TotalBeds -> 64 | I16: Saved in the file | J16: This setup is pre-loaded: Data > Solver opens with it filled in.
A17: BedsPlanted | B17: =SUM(B6:B8) -> 60 | C17: The three bed counts added up | I17: Two starts | J17: Run once from 0 / 0 / 0 and once from 20 / 0 / 0. Both must land on the same mix.
A18: BedsUnused | B18: =TotalBeds-BedsPlanted -> 4 | C18: TotalBeds − BedsPlanted
A19: SeasonProfit | B19: =SUM(G6:G8)-FixedCost -> 42761.665 | C19: Sum of crop profits − FixedCost | I19: Solver setup 2: fewest beds that still cover FixedCost
I20: Set Objective | J20: BreakEvenBeds
A21: Share of costs | I21: To | J21: Min
A22: Cost | B22: $ | C22: Share of total cost | I22: By Changing Variable Cells | J22: B31:B33 (the Setup 2 bed counts)
A23: Labor | B23: =LaborCost -> 104118.34 | C23: =IF($B$26=0,0,B23/$B$26) -> 0.61931576 | I23: Constraint | J23: B31:B33 = integer
A24: Fertilizer | B24: =SUM(E6:E8) -> 44000 | C24: =IF($B$26=0,0,B24/$B$26) -> 0.26172041 | I24: Constraint | J24: B31 <= F13, B32 <= F14, B33 <= F15 (the caps)
A25: Fixed cost | B25: =FixedCost -> 20000 | C25: =IF($B$26=0,0,B25/$B$26) -> 0.11896382 | I25: Constraint | J25: BreakEven_BedsPlanted <= F16 (total beds)
A26: Total cost | B26: =SUM(B23:B25) -> 168118.34 | C26: =SUM(C23:C25) -> 1 | I26: Constraint | J26: BreakEven_TempHours <= BreakEven_TempHoursMax
I27: Constraint | J27: BreakEven_SeasonProfit >= 0
I28: Tick | J28: Make Unconstrained Variables Non-Negative
A29: Setup 2: fewest beds that still cover FixedCost | I29: Solving Method | J29: GRG Nonlinear (if it can't find a feasible answer, start from the Setup 1 mix)
A30: Crop | B30: Beds | C30: Hours | D30: Revenue | E30: Fertilizer | F30: Labor cost | G30: Crop profit
A31: Tomato | B31: 7 | C31: =BreakEven_Tomato_Beds*Tomato_HoursPerWeek*SeasonWeeks*(1+Tomato_DimRate)^BreakEven_Tomato_Beds -> 1227.6918 | D31: =BreakEven_Tomato_Beds*Tomato_Revenue -> 61600 | E31: =BreakEven_Tomato_Beds*Tomato_Fertilizer -> 6160 | F31: =C31*BreakEven_BlendedRate -> 33814.093 | G31: =D31-E31-F31 -> 21625.907
A32: Carrot | B32: 0 | C32: =BreakEven_Carrot_Beds*Carrot_HoursPerWeek*SeasonWeeks*(1+Carrot_DimRate)^BreakEven_Carrot_Beds -> 0 | D32: =BreakEven_Carrot_Beds*Carrot_Revenue -> 0 | E32: =BreakEven_Carrot_Beds*Carrot_Fertilizer -> 0 | F32: =C32*BreakEven_BlendedRate -> 0 | G32: =D32-E32-F32 -> 0
A33: Mesclun | B33: 0 | C33: =BreakEven_Mesclun_Beds*Mesclun_HoursPerWeek*SeasonWeeks*(1+Mesclun_DimRate)^BreakEven_Mesclun_Beds -> 0 | D33: =BreakEven_Mesclun_Beds*Mesclun_Revenue -> 0 | E33: =BreakEven_Mesclun_Beds*Mesclun_Fertilizer -> 0 | F33: =C33*BreakEven_BlendedRate -> 0 | G33: =D33-E33-F33 -> 0
A34: Total | B34: =SUM(B31:B33) -> 7 | C34: =SUM(C31:C33) -> 1227.6918 | D34: =SUM(D31:D33) -> 61600 | E34: =SUM(E31:E33) -> 6160 | F34: =SUM(F31:F33) -> 33814.093 | G34: =SUM(G31:G33) -> 21625.907
A36: TotalHours | B36: =SUM(C31:C33) -> 1227.6918 | C36: Tomato + carrot + mesclun hours
A37: OwnHoursUsed | B37: =MIN(BreakEven_TotalHours,OwnHours) -> 720 | C37: The smaller of TotalHours and OwnHours
A38: TempHours | B38: =BreakEven_TotalHours-BreakEven_OwnHoursUsed -> 507.69177 | C38: Solver keeps this at or below TempHoursMax
A39: TempHoursMax | B39: =MaxTemps*TempHoursEach -> 5760 | C39: MaxTemps × TempHoursEach
A40: LaborCost | B40: =BreakEven_OwnHoursUsed*OwnRate+BreakEven_TempHours*TempRate -> 33814.093 | C40: My hours at OwnRate, temp hours at TempRate
A41: BlendedRate | B41: =IF(BreakEven_TotalHours=0,0,BreakEven_LaborCost/BreakEven_TotalHours) -> 27.54282 | C41: LaborCost ÷ TotalHours (0 when no hours)
A42: BedsPlanted | B42: =SUM(B31:B33) -> 7 | C42: The three bed counts added up
...

Sheet Checks
A1: Checks
A2: Green means met. These test whether the workbook is built right. The published check figures are not on this tab: they are compared in the audit.
A4: Check | B4: Result | C4: Pass?
A5: Main model (Setup 1)
A6: Every bed count is a whole number | B6: =AND(Tomato_Beds=INT(Tomato_Beds),Carrot_Beds=INT(Carrot_Beds),Mesclun_Beds=INT(Mesclun_Beds)) -> TRUE | C6: =IF(B6,"Pass","Fail") -> Pass
A7: Each crop is within its cap (0 to cap) | B7: =AND(Tomato_Beds>=0,Tomato_Beds<=Tomato_Cap,Carrot_Beds>=0,Carrot_Beds<=Carrot_Cap,Mesclun_Beds>=0,Mesclun_Beds<=Mesclun_Cap) -> TRUE | C7: =IF(B7,"Pass","Fail") -> Pass
A8: Total beds are no more than TotalBeds | B8: =BedsPlanted -> 60 | C8: =IF(B8<=TotalBeds,"Pass","Fail") -> Pass
A9: TempHours is no more than MaxTemps × TempHoursEach | B9: =TempHours -> 4557.2161 | C9: =IF(B9<=TempHoursMax,"Pass","Fail") -> Pass
A10: Hand check: one tomato bed takes 99 hours | B10: =Schedules!B9 -> 99 | C10: =IF(ROUND(B10,6)=99,"Pass","Fail") -> Pass
A11: Hand check: two tomato beds take 217.8 hours | B11: =Schedules!B10 -> 217.8 | C11: =IF(ROUND(B11,6)=217.8,"Pass","Fail") -> Pass
A12: No error cells on Schedules | B12: =SUMPRODUCT(--ISERROR(Schedules!A1:AC58)) -> 0 | C12: =IF(B12=0,"Pass","Fail") -> Pass
A13: No error cells on Optimizer | B13: =SUMPRODUCT(--ISERROR(Optimizer!A1:G60)) -> 0 | C13: =IF(B13=0,"Pass","Fail") -> Pass
A14: No error cells on What if | B14: =SUMPRODUCT(--ISERROR('What if'!A1:M80)) -> 0 | C14: =IF(B14=0,"Pass","Fail") -> Pass
A15: Each schedule runs past its cap until MC is above revenue (last row is "No") | B15: =AND(Schedules!H58="No",Schedules!R58="No",Schedules!AB58="No") -> TRUE | C15: =IF(B15,"Pass","Fail") -> Pass
A16: For information: are my 720 hours used up? | B16: =IF(OwnHoursUsed>=OwnHours,"Yes","No") -> Yes | C16: Info
A17: Setup 2 (break-even)
A18: Whole beds, within caps | B18: =AND(BreakEven_Tomato_Beds=INT(BreakEven_Tomato_Beds),BreakEven_Carrot_Beds=INT(BreakEven_Carrot_Beds),BreakEven_Mesclun_Beds=INT(BreakEven_Mesclun_Beds),BreakEven_Tomato_Beds>=0,BreakEven_Tomato_Beds<=Tomato_Cap,BreakEven_Carrot_Beds>=0,BreakEven_Carrot_Beds<=Carrot_Cap,BreakEven_Mesclun_Beds>=0,BreakEven_Mesclun_Beds<=Mesclun_Cap) -> TRUE | C18: =IF(B18,"Pass","Fail") -> Pass
A19: Total beds are no more than TotalBeds | B19: =BreakEven_BedsPlanted -> 7 | C19: =IF(B19<=TotalBeds,"Pass","Fail") -> Pass
A20: TempHours within the limit | B20: =BreakEven_TempHours -> 507.69177 | C20: =IF(B20<=BreakEven_TempHoursMax,"Pass","Fail") -> Pass
A21: Fixed cost covered (SeasonProfit 0 or more) | B21: =BreakEven_SeasonProfit -> 1625.9067 | C21: =IF(B21>=0,"Pass","Fail") -> Pass
A22: What if tab
A23: Whole beds, within caps | B23: =AND(WhatIf_Tomato_Beds=INT(WhatIf_Tomato_Beds),WhatIf_Carrot_Beds=INT(WhatIf_Carrot_Beds),WhatIf_Mesclun_Beds=INT(WhatIf_Mesclun_Beds),WhatIf_Tomato_Beds>=0,WhatIf_Tomato_Beds<=Tomato_Cap,WhatIf_Carrot_Beds>=0,WhatIf_Carrot_Beds<=Carrot_Cap,WhatIf_Mesclun_Beds>=0,WhatIf_Mesclun_Beds<=Mesclun_Cap) -> TRUE | C23: =IF(B23,"Pass","Fail") -> Pass
A24: Total beds are no more than TotalBeds | B24: =WhatIf_BedsPlanted -> 60 | C24: =IF(B24<=TotalBeds,"Pass","Fail") -> Pass
A25: Temp paid hours within 5,760 | B25: =WhatIf_TempPaidHours -> 4849.1176 | C25: =IF(B25<=WhatIf_TempPaidHoursMax,"Pass","Fail") -> Pass
A26: Hand check: a temp's week averages 94.5% | B26: =TempEfficiency -> 0.945 | C26: =IF(ROUND(B26,6)=0.945,"Pass","Fail") -> Pass
A27: Hand check: my week averages 96.5% | B27: =OwnEfficiency -> 0.965 | C27: =IF(ROUND(B27,6)=0.965,"Pass","Fail") -> Pass
A29: Checks you run by hand (record the results in the spec's Audit findings)
A30: • Two Solver starts: Setup 1 from 0 / 0 / 0 and from 20 / 0 / 0 land on the same mix. If not, that is a finding.
A31: • Farm Profit Lab: at least one marginal cost from the middle of a schedule matches the Lab.
A32: • Formulas, not typed numbers: click calculated cells and confirm each is a formula using the named inputs.
A33: • Zero fatigue: set HourlyLoss and DailyPenalty to 0%, run the What if Solver, and compare with Setup 1. Mix and profit must match exactly. Then set both back to 1%.
A34: • Published check figures: compare against the table in the spec's Validation rules.

Sheet Answer Report 3
A1: Microsoft Excel 16.112 Answer Report
A2: Worksheet: [model.xlsx]What if
A3: Report Created: 10/27/26 4:24:38 PM
A4: Result: Solver found a solution. All constraints and optimality conditions are satisfied.
A5: Solver Engine
B6: Engine: GRG Nonlinear
B7: Solution Time: 865.734 Seconds.
B8: Iterations: 0 Subproblems: 2
A9: Solver Options
B10: Max Time Unlimited, Iterations Unlimited, Precision 0.000001, Use Automatic Scaling
B11: Convergence 0.0001, Population Size 100, Random Seed 0, Derivatives Forward, Require Bounds
B12: Max Subproblems Unlimited, Max Integer Sols Unlimited, Integer Tolerance 0%, Assume NonNegative
A14: Objective Cell (Max)
B15: Cell | C15: Name | D15: Original Value | E15: Final Value
B16: $B$43 | C16: WhatIf_SeasonProfit | D16: -20000 | E16: 37708.143
A19: Variable Cells
B20: Cell | C20: Name | D20: Original Value | E20: Final Value | F20: Integer
B21: $B$30 | C21: WhatIf_Tomato_Beds | D21: 0 | E21: 10 | F21: Integer
B22: $B$31 | C22: WhatIf_Carrot_Beds | D22: 0 | E22: 20 | F22: Integer
B23: $B$32 | C23: WhatIf_Mesclun_Beds | D23: 0 | E23: 30 | F23: Integer
A26: Constraints
B27: Cell | C27: Name | D27: Cell Value | E27: Formula | F27: Status | G27: Slack
B28: $B$42 | C28: WhatIf_BedsPlanted | D28: 60 | E28: $B$42<=$I$39 | F28: Not Binding | G28: 4
B29: $B$37 | C29: WhatIf_TempPaidHours | D29: 4848.7014 | E29: $B$37<=$B$38 | F29: Not Binding | G29: 911.29858
B30: $B$31 | C30: WhatIf_Carrot_Beds | D30: 20 | E30: $B$31<=$I$37 | F30: Binding | G30: 0
B31: $B$32 | C31: WhatIf_Mesclun_Beds | D31: 30 | E31: $B$32<=$I$38 | F31: Binding | G31: 0
B32: $B$30 | C32: WhatIf_Tomato_Beds | D32: 10 | E32: $B$30<=$I$36 | F32: Not Binding | G32: 10
B33: $B$30:$B$32=Integer

Sheet Answer Report 7
A1: Microsoft Excel 16.112 Answer Report
A2: Worksheet: [model.xlsx]What if
A3: Report Created: 10/29/26 7:35:47 PM
A4: Result: Solver found a solution. All constraints and optimality conditions are satisfied.
A5: Solver Engine
B6: Engine: GRG Nonlinear
B7: Solution Time: 803.118 Seconds.
B8: Iterations: 0 Subproblems: 2
A9: Solver Options
B10: Max Time Unlimited, Iterations Unlimited, Precision 0.000001, Use Automatic Scaling
B11: Convergence 0.0001, Population Size 100, Random Seed 0, Derivatives Forward, Require Bounds
B12: Max Subproblems Unlimited, Max Integer Sols Unlimited, Integer Tolerance 0%, Assume NonNegative
A14: Objective Cell (Max)
B15: Cell | C15: Name | D15: Original Value | E15: Final Value
B16: $B$43 | C16: WhatIf_SeasonProfit | D16: 37693.931 | E16: 37693.931
A19: Variable Cells
B20: Cell | C20: Name | D20: Original Value | E20: Final Value | F20: Integer
B21: $B$30 | C21: WhatIf_Tomato_Beds | D21: 10 | E21: 10 | F21: Integer
B22: $B$31 | C22: WhatIf_Carrot_Beds | D22: 20 | E22: 20 | F22: Integer
B23: $B$32 | C23: WhatIf_Mesclun_Beds | D23: 30 | E23: 30 | F23: Integer
A26: Constraints
B27: Cell | C27: Name | D27: Cell Value | E27: Formula | F27: Status | G27: Slack
B28: $B$42 | C28: WhatIf_BedsPlanted | D28: 60 | E28: $B$42<=$I$39 | F28: Not Binding | G28: 4
B29: $B$37 | C29: WhatIf_TempPaidHours | D29: 4849.1176 | E29: $B$37<=$B$38 | F29: Not Binding | G29: 910.88242
B30: $B$31 | C30: WhatIf_Carrot_Beds | D30: 20 | E30: $B$31<=$I$37 | F30: Binding | G30: 0
B31: $B$32 | C31: WhatIf_Mesclun_Beds | D31: 30 | E31: $B$32<=$I$38 | F31: Binding | G31: 0
B32: $B$30 | C32: WhatIf_Tomato_Beds | D32: 10 | E32: $B$30<=$I$36 | F32: Not Binding | G32: 10
B33: $B$30:$B$32=Integer

Sheet What if
A1: What if workers got tired throughout the week?
A2: A side interest project, not part of the case's model. Own bed counts and own Solver setup; nothing here changes the other tabs.
A4: A temp's week: efficiency by day and hour
A5: Day \ hour | B5: 1 | C5: 2 | D5: 3 | E5: 4 | F5: 5 | G5: 6 | H5: 7 | I5: 8 | J5: 9 | K5: 10 | L5: 11 | M5: 12
A6: 1 | B6: =IF(AND($A6<=TempDaysPerWeek,B$5<=TempDayHours),1-DailyPenalty*($A6-1)-HourlyLoss*(B$5-1),"") -> 1 | C6: =IF(AND($A6<=TempDaysPerWeek,C$5<=TempDayHours),1-DailyPenalty*($A6-1)-HourlyLoss*(C$5-1),"") -> 0.99 | D6: =IF(AND($A6<=TempDaysPerWeek,D$5<=TempDayHours),1-DailyPenalty*($A6-1)-HourlyLoss*(D$5-1),"") -> 0.98 | E6: =IF(AND($A6<=TempDaysPerWeek,E$5<=TempDayHours),1-DailyPenalty*($A6-1)-HourlyLoss*(E$5-1),"") -> 0.97 | F6: =IF(AND($A6<=TempDaysPerWeek,F$5<=TempDayHours),1-DailyPenalty*($A6-1)-HourlyLoss*(F$5-1),"") -> 0.96 | G6: =IF(AND($A6<=TempDaysPerWeek,G$5<=TempDayHours),1-DailyPenalty*($A6-1)-HourlyLoss*(G$5-1),"") -> 0.95 | H6: =IF(AND($A6<=TempDaysPerWeek,H$5<=TempDayHours),1-DailyPenalty*($A6-1)-HourlyLoss*(H$5-1),"") -> 0.94 | I6: =IF(AND($A6<=TempDaysPerWeek,I$5<=TempDayHours),1-DailyPenalty*($A6-1)-HourlyLoss*(I$5-1),"") -> 0.93 | ... M6: =IF(AND($A6<=TempDaysPerWeek,M$5<=TempDayHours),1-DailyPenalty*($A6-1)-HourlyLoss*(M$5-1),"")
A7: 2 | B7: =IF(AND($A7<=TempDaysPerWeek,B$5<=TempDayHours),1-DailyPenalty*($A7-1)-HourlyLoss*(B$5-1),"") -> 0.99 | C7: =IF(AND($A7<=TempDaysPerWeek,C$5<=TempDayHours),1-DailyPenalty*($A7-1)-HourlyLoss*(C$5-1),"") -> 0.98 | D7: =IF(AND($A7<=TempDaysPerWeek,D$5<=TempDayHours),1-DailyPenalty*($A7-1)-HourlyLoss*(D$5-1),"") -> 0.97 | E7: =IF(AND($A7<=TempDaysPerWeek,E$5<=TempDayHours),1-DailyPenalty*($A7-1)-HourlyLoss*(E$5-1),"") -> 0.96 | F7: =IF(AND($A7<=TempDaysPerWeek,F$5<=TempDayHours),1-DailyPenalty*($A7-1)-HourlyLoss*(F$5-1),"") -> 0.95 | G7: =IF(AND($A7<=TempDaysPerWeek,G$5<=TempDayHours),1-DailyPenalty*($A7-1)-HourlyLoss*(G$5-1),"") -> 0.94 | H7: =IF(AND($A7<=TempDaysPerWeek,H$5<=TempDayHours),1-DailyPenalty*($A7-1)-HourlyLoss*(H$5-1),"") -> 0.93 | I7: =IF(AND($A7<=TempDaysPerWeek,I$5<=TempDayHours),1-DailyPenalty*($A7-1)-HourlyLoss*(I$5-1),"") -> 0.92 | ... M7: =IF(AND($A7<=TempDaysPerWeek,M$5<=TempDayHours),1-DailyPenalty*($A7-1)-HourlyLoss*(M$5-1),"")
A8: 3 | B8: =IF(AND($A8<=TempDaysPerWeek,B$5<=TempDayHours),1-DailyPenalty*($A8-1)-HourlyLoss*(B$5-1),"") -> 0.98 | C8: =IF(AND($A8<=TempDaysPerWeek,C$5<=TempDayHours),1-DailyPenalty*($A8-1)-HourlyLoss*(C$5-1),"") -> 0.97 | D8: =IF(AND($A8<=TempDaysPerWeek,D$5<=TempDayHours),1-DailyPenalty*($A8-1)-HourlyLoss*(D$5-1),"") -> 0.96 | E8: =IF(AND($A8<=TempDaysPerWeek,E$5<=TempDayHours),1-DailyPenalty*($A8-1)-HourlyLoss*(E$5-1),"") -> 0.95 | F8: =IF(AND($A8<=TempDaysPerWeek,F$5<=TempDayHours),1-DailyPenalty*($A8-1)-HourlyLoss*(F$5-1),"") -> 0.94 | G8: =IF(AND($A8<=TempDaysPerWeek,G$5<=TempDayHours),1-DailyPenalty*($A8-1)-HourlyLoss*(G$5-1),"") -> 0.93 | H8: =IF(AND($A8<=TempDaysPerWeek,H$5<=TempDayHours),1-DailyPenalty*($A8-1)-HourlyLoss*(H$5-1),"") -> 0.92 | I8: =IF(AND($A8<=TempDaysPerWeek,I$5<=TempDayHours),1-DailyPenalty*($A8-1)-HourlyLoss*(I$5-1),"") -> 0.91 | ... M8: =IF(AND($A8<=TempDaysPerWeek,M$5<=TempDayHours),1-DailyPenalty*($A8-1)-HourlyLoss*(M$5-1),"")
A9: 4 | B9: =IF(AND($A9<=TempDaysPerWeek,B$5<=TempDayHours),1-DailyPenalty*($A9-1)-HourlyLoss*(B$5-1),"") -> 0.97 | C9: =IF(AND($A9<=TempDaysPerWeek,C$5<=TempDayHours),1-DailyPenalty*($A9-1)-HourlyLoss*(C$5-1),"") -> 0.96 | D9: =IF(AND($A9<=TempDaysPerWeek,D$5<=TempDayHours),1-DailyPenalty*($A9-1)-HourlyLoss*(D$5-1),"") -> 0.95 | E9: =IF(AND($A9<=TempDaysPerWeek,E$5<=TempDayHours),1-DailyPenalty*($A9-1)-HourlyLoss*(E$5-1),"") -> 0.94 | F9: =IF(AND($A9<=TempDaysPerWeek,F$5<=TempDayHours),1-DailyPenalty*($A9-1)-HourlyLoss*(F$5-1),"") -> 0.93 | G9: =IF(AND($A9<=TempDaysPerWeek,G$5<=TempDayHours),1-DailyPenalty*($A9-1)-HourlyLoss*(G$5-1),"") -> 0.92 | H9: =IF(AND($A9<=TempDaysPerWeek,H$5<=TempDayHours),1-DailyPenalty*($A9-1)-HourlyLoss*(H$5-1),"") -> 0.91 | I9: =IF(AND($A9<=TempDaysPerWeek,I$5<=TempDayHours),1-DailyPenalty*($A9-1)-HourlyLoss*(I$5-1),"") -> 0.9 | ... M9: =IF(AND($A9<=TempDaysPerWeek,M$5<=TempDayHours),1-DailyPenalty*($A9-1)-HourlyLoss*(M$5-1),"")
A10: 5 | B10: =IF(AND($A10<=TempDaysPerWeek,B$5<=TempDayHours),1-DailyPenalty*($A10-1)-HourlyLoss*(B$5-1),"") -> 0.96 | C10: =IF(AND($A10<=TempDaysPerWeek,C$5<=TempDayHours),1-DailyPenalty*($A10-1)-HourlyLoss*(C$5-1),"") -> 0.95 | D10: =IF(AND($A10<=TempDaysPerWeek,D$5<=TempDayHours),1-DailyPenalty*($A10-1)-HourlyLoss*(D$5-1),"") -> 0.94 | E10: =IF(AND($A10<=TempDaysPerWeek,E$5<=TempDayHours),1-DailyPenalty*($A10-1)-HourlyLoss*(E$5-1),"") -> 0.93 | F10: =IF(AND($A10<=TempDaysPerWeek,F$5<=TempDayHours),1-DailyPenalty*($A10-1)-HourlyLoss*(F$5-1),"") -> 0.92 | G10: =IF(AND($A10<=TempDaysPerWeek,G$5<=TempDayHours),1-DailyPenalty*($A10-1)-HourlyLoss*(G$5-1),"") -> 0.91 | H10: =IF(AND($A10<=TempDaysPerWeek,H$5<=TempDayHours),1-DailyPenalty*($A10-1)-HourlyLoss*(H$5-1),"") -> 0.9 | I10: =IF(AND($A10<=TempDaysPerWeek,I$5<=TempDayHours),1-DailyPenalty*($A10-1)-HourlyLoss*(I$5-1),"") -> 0.89 | ... M10: =IF(AND($A10<=TempDaysPerWeek,M$5<=TempDayHours),1-DailyPenalty*($A10-1)-HourlyLoss*(M$5-1),"")
A11: 6 | B11: =IF(AND($A11<=TempDaysPerWeek,B$5<=TempDayHours),1-DailyPenalty*($A11-1)-HourlyLoss*(B$5-1),"") | C11: =IF(AND($A11<=TempDaysPerWeek,C$5<=TempDayHours),1-DailyPenalty*($A11-1)-HourlyLoss*(C$5-1),"") | D11: =IF(AND($A11<=TempDaysPerWeek,D$5<=TempDayHours),1-DailyPenalty*($A11-1)-HourlyLoss*(D$5-1),"") | E11: =IF(AND($A11<=TempDaysPerWeek,E$5<=TempDayHours),1-DailyPenalty*($A11-1)-HourlyLoss*(E$5-1),"") | F11: =IF(AND($A11<=TempDaysPerWeek,F$5<=TempDayHours),1-DailyPenalty*($A11-1)-HourlyLoss*(F$5-1),"") | G11: =IF(AND($A11<=TempDaysPerWeek,G$5<=TempDayHours),1-DailyPenalty*($A11-1)-HourlyLoss*(G$5-1),"") | H11: =IF(AND($A11<=TempDaysPerWeek,H$5<=TempDayHours),1-DailyPenalty*($A11-1)-HourlyLoss*(H$5-1),"") | I11: =IF(AND($A11<=TempDaysPerWeek,I$5<=TempDayHours),1-DailyPenalty*($A11-1)-HourlyLoss*(I$5-1),"") | ... M11: =IF(AND($A11<=TempDaysPerWeek,M$5<=TempDayHours),1-DailyPenalty*($A11-1)-HourlyLoss*(M$5-1),"")
A12: 7 | B12: =IF(AND($A12<=TempDaysPerWeek,B$5<=TempDayHours),1-DailyPenalty*($A12-1)-HourlyLoss*(B$5-1),"") | C12: =IF(AND($A12<=TempDaysPerWeek,C$5<=TempDayHours),1-DailyPenalty*($A12-1)-HourlyLoss*(C$5-1),"") | D12: =IF(AND($A12<=TempDaysPerWeek,D$5<=TempDayHours),1-DailyPenalty*($A12-1)-HourlyLoss*(D$5-1),"") | E12: =IF(AND($A12<=TempDaysPerWeek,E$5<=TempDayHours),1-DailyPenalty*($A12-1)-HourlyLoss*(E$5-1),"") | F12: =IF(AND($A12<=TempDaysPerWeek,F$5<=TempDayHours),1-DailyPenalty*($A12-1)-HourlyLoss*(F$5-1),"") | G12: =IF(AND($A12<=TempDaysPerWeek,G$5<=TempDayHours),1-DailyPenalty*($A12-1)-HourlyLoss*(G$5-1),"") | H12: =IF(AND($A12<=TempDaysPerWeek,H$5<=TempDayHours),1-DailyPenalty*($A12-1)-HourlyLoss*(H$5-1),"") | I12: =IF(AND($A12<=TempDaysPerWeek,I$5<=TempDayHours),1-DailyPenalty*($A12-1)-HourlyLoss*(I$5-1),"") | ... M12: =IF(AND($A12<=TempDaysPerWeek,M$5<=TempDayHours),1-DailyPenalty*($A12-1)-HourlyLoss*(M$5-1),"")
A14: My week: efficiency by day and hour
A15: Day \ hour | B15: 1 | C15: 2 | D15: 3 | E15: 4 | F15: 5 | G15: 6 | H15: 7 | I15: 8 | J15: 9 | K15: 10 | L15: 11 | M15: 12
A16: 1 | B16: =IF(AND($A16<=OwnDaysPerWeek,B$15<=OwnDayHours),1-DailyPenalty*($A16-1)-HourlyLoss*(B$15-1),"") -> 1 | C16: =IF(AND($A16<=OwnDaysPerWeek,C$15<=OwnDayHours),1-DailyPenalty*($A16-1)-HourlyLoss*(C$15-1),"") -> 0.99 | D16: =IF(AND($A16<=OwnDaysPerWeek,D$15<=OwnDayHours),1-DailyPenalty*($A16-1)-HourlyLoss*(D$15-1),"") -> 0.98 | E16: =IF(AND($A16<=OwnDaysPerWeek,E$15<=OwnDayHours),1-DailyPenalty*($A16-1)-HourlyLoss*(E$15-1),"") -> 0.97 | F16: =IF(AND($A16<=OwnDaysPerWeek,F$15<=OwnDayHours),1-DailyPenalty*($A16-1)-HourlyLoss*(F$15-1),"") | G16: =IF(AND($A16<=OwnDaysPerWeek,G$15<=OwnDayHours),1-DailyPenalty*($A16-1)-HourlyLoss*(G$15-1),"") | H16: =IF(AND($A16<=OwnDaysPerWeek,H$15<=OwnDayHours),1-DailyPenalty*($A16-1)-HourlyLoss*(H$15-1),"") | I16: =IF(AND($A16<=OwnDaysPerWeek,I$15<=OwnDayHours),1-DailyPenalty*($A16-1)-HourlyLoss*(I$15-1),"") | ... M16: =IF(AND($A16<=OwnDaysPerWeek,M$15<=OwnDayHours),1-DailyPenalty*($A16-1)-HourlyLoss*(M$15-1),"")
A17: 2 | B17: =IF(AND($A17<=OwnDaysPerWeek,B$15<=OwnDayHours),1-DailyPenalty*($A17-1)-HourlyLoss*(B$15-1),"") -> 0.99 | C17: =IF(AND($A17<=OwnDaysPerWeek,C$15<=OwnDayHours),1-DailyPenalty*($A17-1)-HourlyLoss*(C$15-1),"") -> 0.98 | D17: =IF(AND($A17<=OwnDaysPerWeek,D$15<=OwnDayHours),1-DailyPenalty*($A17-1)-HourlyLoss*(D$15-1),"") -> 0.97 | E17: =IF(AND($A17<=OwnDaysPerWeek,E$15<=OwnDayHours),1-DailyPenalty*($A17-1)-HourlyLoss*(E$15-1),"") -> 0.96 | F17: =IF(AND($A17<=OwnDaysPerWeek,F$15<=OwnDayHours),1-DailyPenalty*($A17-1)-HourlyLoss*(F$15-1),"") | G17: =IF(AND($A17<=OwnDaysPerWeek,G$15<=OwnDayHours),1-DailyPenalty*($A17-1)-HourlyLoss*(G$15-1),"") | H17: =IF(AND($A17<=OwnDaysPerWeek,H$15<=OwnDayHours),1-DailyPenalty*($A17-1)-HourlyLoss*(H$15-1),"") | I17: =IF(AND($A17<=OwnDaysPerWeek,I$15<=OwnDayHours),1-DailyPenalty*($A17-1)-HourlyLoss*(I$15-1),"") | ... M17: =IF(AND($A17<=OwnDaysPerWeek,M$15<=OwnDayHours),1-DailyPenalty*($A17-1)-HourlyLoss*(M$15-1),"")
A18: 3 | B18: =IF(AND($A18<=OwnDaysPerWeek,B$15<=OwnDayHours),1-DailyPenalty*($A18-1)-HourlyLoss*(B$15-1),"") -> 0.98 | C18: =IF(AND($A18<=OwnDaysPerWeek,C$15<=OwnDayHours),1-DailyPenalty*($A18-1)-HourlyLoss*(C$15-1),"") -> 0.97 | D18: =IF(AND($A18<=OwnDaysPerWeek,D$15<=OwnDayHours),1-DailyPenalty*($A18-1)-HourlyLoss*(D$15-1),"") -> 0.96 | E18: =IF(AND($A18<=OwnDaysPerWeek,E$15<=OwnDayHours),1-DailyPenalty*($A18-1)-HourlyLoss*(E$15-1),"") -> 0.95 | F18: =IF(AND($A18<=OwnDaysPerWeek,F$15<=OwnDayHours),1-DailyPenalty*($A18-1)-HourlyLoss*(F$15-1),"") | G18: =IF(AND($A18<=OwnDaysPerWeek,G$15<=OwnDayHours),1-DailyPenalty*($A18-1)-HourlyLoss*(G$15-1),"") | H18: =IF(AND($A18<=OwnDaysPerWeek,H$15<=OwnDayHours),1-DailyPenalty*($A18-1)-HourlyLoss*(H$15-1),"") | I18: =IF(AND($A18<=OwnDaysPerWeek,I$15<=OwnDayHours),1-DailyPenalty*($A18-1)-HourlyLoss*(I$15-1),"") | ... M18: =IF(AND($A18<=OwnDaysPerWeek,M$15<=OwnDayHours),1-DailyPenalty*($A18-1)-HourlyLoss*(M$15-1),"")
A19: 4 | B19: =IF(AND($A19<=OwnDaysPerWeek,B$15<=OwnDayHours),1-DailyPenalty*($A19-1)-HourlyLoss*(B$15-1),"") -> 0.97 | C19: =IF(AND($A19<=OwnDaysPerWeek,C$15<=OwnDayHours),1-DailyPenalty*($A19-1)-HourlyLoss*(C$15-1),"") -> 0.96 | D19: =IF(AND($A19<=OwnDaysPerWeek,D$15<=OwnDayHours),1-DailyPenalty*($A19-1)-HourlyLoss*(D$15-1),"") -> 0.95 | E19: =IF(AND($A19<=OwnDaysPerWeek,E$15<=OwnDayHours),1-DailyPenalty*($A19-1)-HourlyLoss*(E$15-1),"") -> 0.94 | F19: =IF(AND($A19<=OwnDaysPerWeek,F$15<=OwnDayHours),1-DailyPenalty*($A19-1)-HourlyLoss*(F$15-1),"") | G19: =IF(AND($A19<=OwnDaysPerWeek,G$15<=OwnDayHours),1-DailyPenalty*($A19-1)-HourlyLoss*(G$15-1),"") | H19: =IF(AND($A19<=OwnDaysPerWeek,H$15<=OwnDayHours),1-DailyPenalty*($A19-1)-HourlyLoss*(H$15-1),"") | I19: =IF(AND($A19<=OwnDaysPerWeek,I$15<=OwnDayHours),1-DailyPenalty*($A19-1)-HourlyLoss*(I$15-1),"") | ... M19: =IF(AND($A19<=OwnDaysPerWeek,M$15<=OwnDayHours),1-DailyPenalty*($A19-1)-HourlyLoss*(M$15-1),"")
A20: 5 | B20: =IF(AND($A20<=OwnDaysPerWeek,B$15<=OwnDayHours),1-DailyPenalty*($A20-1)-HourlyLoss*(B$15-1),"") -> 0.96 | C20: =IF(AND($A20<=OwnDaysPerWeek,C$15<=OwnDayHours),1-DailyPenalty*($A20-1)-HourlyLoss*(C$15-1),"") -> 0.95 | D20: =IF(AND($A20<=OwnDaysPerWeek,D$15<=OwnDayHours),1-DailyPenalty*($A20-1)-HourlyLoss*(D$15-1),"") -> 0.94 | E20: =IF(AND($A20<=OwnDaysPerWeek,E$15<=OwnDayHours),1-DailyPenalty*($A20-1)-HourlyLoss*(E$15-1),"") -> 0.93 | F20: =IF(AND($A20<=OwnDaysPerWeek,F$15<=OwnDayHours),1-DailyPenalty*($A20-1)-HourlyLoss*(F$15-1),"") | G20: =IF(AND($A20<=OwnDaysPerWeek,G$15<=OwnDayHours),1-DailyPenalty*($A20-1)-HourlyLoss*(G$15-1),"") | H20: =IF(AND($A20<=OwnDaysPerWeek,H$15<=OwnDayHours),1-DailyPenalty*($A20-1)-HourlyLoss*(H$15-1),"") | I20: =IF(AND($A20<=OwnDaysPerWeek,I$15<=OwnDayHours),1-DailyPenalty*($A20-1)-HourlyLoss*(I$15-1),"") | ... M20: =IF(AND($A20<=OwnDaysPerWeek,M$15<=OwnDayHours),1-DailyPenalty*($A20-1)-HourlyLoss*(M$15-1),"")
